<?xml version='1.0'?>
<sdf version='1.4'>

  <model name="basic_car">
    <static>false</static>
    <link name='chassis'>
        
        <pose>0 0 .1 0 0 0</pose>


        <visual name='visual'>
          <pose>0 0 0.45 0 0 -1.5708</pose>
          <geometry>
            <mesh>
              <uri>model://car_019/meshes/car_019.dae</uri>
              <scale>1 1 1</scale>
            </mesh>
          </geometry>
        </visual>
        
        <collision name='collision'>
          <geometry>
            <box>
              <size>3.8 1.4 0.3</size>
            </box>
          </geometry>
        </collision>
        

    </link>
    
    <link name="left_wheel">
        <pose>1.25 0.8 0.2 0 1.5707 1.5707</pose>
        <collision name="collision">
          <geometry>
            <cylinder>
              <radius>.3</radius>
              <length>.05</length>
            </cylinder>
          </geometry>
        </collision>
        <visual name="visual">
          <geometry>
            <cylinder>
              <radius>.3</radius>
              <length>.05</length>
            </cylinder>
          </geometry>
        </visual>
    </link>
    <link name="right_wheel">
        <pose>1.25 -0.8 0.2 0 1.5707 1.5707</pose>
        <collision name="collision">
          <geometry>
            <cylinder>
              <radius>.3</radius>
              <length>.05</length>
            </cylinder>
          </geometry>
        </collision>
        <visual name="visual">
          <geometry>
            <cylinder>
              <radius>.3</radius>
              <length>.05</length>
            </cylinder>
          </geometry>
        </visual>

  </link>
    <link name="rear_left_wheel">
        <pose>-1.25 0.8 0.2 0 1.5707 1.5707</pose>
        <collision name="collision">
          <geometry>
            <cylinder>
              <radius>.3</radius>
              <length>.05</length>
            </cylinder>
          </geometry>
        </collision>
        <visual name="visual">
          <geometry>
            <cylinder>
              <radius>.3</radius>
              <length>.05</length>
            </cylinder>
          </geometry>
        </visual>
    </link>
    <link name="rear_right_wheel">
        <pose>-1.25 -0.8 0.2 0 1.5707 1.5707</pose>
        <collision name="collision">
          <geometry>
            <cylinder>
              <radius>.3</radius>
              <length>.05</length>
            </cylinder>
          </geometry>
        </collision>
        <visual name="visual">
          <geometry>
            <cylinder>
              <radius>.3</radius>
              <length>.05</length>
            </cylinder>
          </geometry>
        </visual>
  </link>
    
    <joint type="revolute" name="left_wheel_hinge">
        <pose>0 0 -0.03 0 0 0</pose>
        <child>left_wheel</child>
        <parent>chassis</parent>
        <axis>
            <xyz>0 1 0</xyz>
        </axis>
    </joint>

    <joint type="revolute" name="right_wheel_hinge">
        <pose>0 0 0.03 0 0 0</pose>
        <child>right_wheel</child>
        <parent>chassis</parent>
        <axis>
            <xyz>0 1 0</xyz>
        </axis>
    </joint>
    
    <joint type="revolute" name="rear_left_wheel_hinge">
        <pose>0 0 -0.03 0 0 0</pose>
        <child>rear_left_wheel</child>
        <parent>chassis</parent>
        <axis>
            <xyz>0 1 0</xyz>
        </axis>
    </joint>

    <joint type="revolute" name="rear_right_wheel_hinge">
        <pose>0 0 0.03 0 0 0</pose>
        <child>rear_right_wheel</child>
        <parent>chassis</parent>
        <axis>
            <xyz>0 1 0</xyz>
        </axis>
    </joint>

    <link name="sensor">
      <sensor name="laser" type="ray">
        <pose>1 0 1 0 0 0</pose>
        <ray>
          <scan>
            <horizontal>
              <samples>180</samples>
              <resolution>1.000000</resolution>
              <min_angle>-2.268928</min_angle>
              <max_angle>2.268928</max_angle>
            </horizontal>
          </scan>
          <range>
            <min>0.080000</min>
            <max>10</max>
            <resolution>0.010000</resolution>
          </range>
        </ray>

        <plugin name='laser_controller' filename='libgazebo_ros_laser.so'>
          <gaussianNoise>0.005</gaussianNoise>
          <alwaysOn>1</alwaysOn>
          <updateRate>20</updateRate>
          <topicName>scan</topicName>
          <frameName>laser</frameName>
        </plugin>
        <update_rate>20</update_rate>
      </sensor>
      </link>

  <include>
    <uri>model://hokuyo</uri>
    <pose>0.2 0 1 0 0 0</pose>
  </include>
  <joint name="hokuyo_joint" type="fixed">
    <child>hokuyo::link</child>
    <parent>chassis</parent>
  </joint> 
  
  
  </model>
</sdf>
